Workbook

Sheet 🏢 EMPRESAS
A1: IDEmpresa | B1: RazaoSocial | C1: CNPJ_CPF | D1: InscricaoEstadual | E1: Abertura | F1: TipoCliente | G1: RamoCliente | H1: SócioAdministrador | I1: Logradouro | J1: Numero | K1: Complemento | L1: Bairro | M1: CEP | N1: Municipio | O1: Estado | P1: EmailCliente | Q1: TelefoneCliente | R1: Idade
A2: 1 | B2: TKJ Gerenciamento LTDA | C2: 13.625.833/0001-90 | D2: 119116185115 | E2: 40669 | F2: PJ | G2: Aluguel de Máquinas e Equipamentos | H2: Karina R. Hornink | I2: Alameda Afonso Schmidt | J2: 119 | K2: Conj 67 Sala 02 | L2: Santa Teresinha | M2: 02450-000 | N2: São Paulo | O2: SP | P2: administrativo@tkjgerenciamento.com.br | Q2: (11) 2972-4277 | R2: =DATEDIF(E2,TODAY(),"y") & " Anos, " & DATEDIF(E2,TODAY(),"ym") & " meses e " & DATEDIF(E2,TODAY(),"md") & " dias" -> 15 Anos, 0 meses e 4 dias
A3: 2 | B3: Finita Gerenciamento e Participacoes SA | C3: 48.210.902/0001-89 | E3: 44840 | F3: PJ | G3: Holdings | H3: Karina R. Hornink | I3: Alameda Afonso Schmidt | J3: 119 | K3: Conj 67 Sala 03 | L3: Santa Teresinha | M3: 02450-000 | N3: São Paulo | O3: SP | P3: finitaempreendimentos@gmail.com | Q3: (11) 2972-4277 | R3: =DATEDIF(E3,TODAY(),"y") & " Anos, " & DATEDIF(E3,TODAY(),"ym") & " meses e " & DATEDIF(E3,TODAY(),"md") & " dias" -> 3 Anos, 7 meses e 4 dias
A4: 3 | B4: Landkraft Locacoes LTDA | C4: 61.866.923/0001-15 | E4: 45860 | F4: PJ | G4: Aluguel de Máquinas e Equipamentos | H4: Karina R. Hornink | I4: Rua Maj Dantas Cortez | J4: 118 | K4: Anexo 122 Esq Dr Jose N57 Sala 01 | L4: Vila Gustavo | M4: 02206-000 | N4: São Paulo | O4: SP | P4: administrativo@landkraft.com.br | Q4: (11) 99360-5870 | R4: =DATEDIF(E4,TODAY(),"y") & " Anos, " & DATEDIF(E4,TODAY(),"ym") & " meses e " & DATEDIF(E4,TODAY(),"md") & " dias" -> 0 Anos, 9 meses e 18 dias
A5: 4 | B5: Thais Regueira Hornink | C5: 395.164.688-88

Sheet 🚛 FROTA
A1: IDVeiculo | B1: Placa | C1: Renavam | D1: Marca | E1: Modelo | F1: Tipagem | G1: Especie | H1: AnoFabricacao | I1: AnoModelo | J1: TabelaFipe | K1: Implemento | L1: ValorImplemento | M1: ValorTotal | N1: Status | O1: ValorVenda | P1: StatusBancario | Q1: Restricoes | R1: Observacoes
A2: 1 | B2: CLH8437 | C2: 435742442 | D2: Ford | E2: Cargo 1415 | F2: Caminhão | G2: Toco | H2: 1987 | I2: 1987 | J2: 0 | K2: Prancha | L2: 0 | M2: =SUM(L2,J2) -> 0 | N2: Vendido | O2: 70000
A3: 2 | B3: LOX6E32 | C3: 814305121 | D3: Volkswagen | E3: 15.180 Worker | F3: Caminhão | G3: Toco | H3: 2003 | I3: 2004 | J3: 0 | K3: Prancha | L3: 0 | M3: =SUM(L3,J3) -> 0 | N3: Vendido | O3: 100000
A4: 3 | B4: EET8B32 | C4: 119604302 | D4: Fiat | E4: Palio Fire 1.0 | F4: Carro | H4: 2008 | I4: 2009 | J4: 0 | L4: 0 | M4: =SUM(L4,J4) -> 0 | N4: Vendido | O4: 15000
A5: 4 | B5: KJX8J96 | C5: 980404940 | D5: Volkswagen | E5: 8.150E Delivery | F5: Caminhão | G5: 3/4 | H5: 2008 | I5: 2009 | J5: 0 | K5: Baú | L5: 0 | M5: =SUM(L5,J5) -> 0 | N5: Vendido | O5: 92500
A6: 5 | B6: ANP7H74 | C6: 344934950 | D6: Volkswagen | E6: 13.180 Constellation | F6: Caminhão | G6: Toco | H6: 2011 | I6: 2011 | J6: 0 | K6: Tanque | L6: 0 | M6: =SUM(L6,J6) -> 0 | N6: Vendido | O6: 230000
A7: 6 | B7: EVF8I83 | C7: 324418264 | D7: Volkswagen | E7: 13.180 Constellation | F7: Caminhão | G7: Toco | H7: 2011 | I7: 2011 | J7: 189797 | K7: Munck | L7: 70000 | M7: =SUM(L7,J7) -> 259797 | N7: Frota | P7: Santander Leasing Reneg | Q7: Financeira | R7: Locado
A8: 7 | B8: EUK4135 | C8: 411870114 | D8: Volkswagen | E8: 9.150 Delivery | F8: Caminhão | G8: 3/4 | H8: 2011 | I8: 2012 | J8: 0 | K8: Carroceria | L8: 0 | M8: =SUM(L8,J8) -> 0 | N8: Vendido | O8: 133000
A9: 8 | B9: AWC3252 | C9: 492209359 | D9: Ford | E9: Cargo 1519 | F9: Caminhão | G9: Toco | H9: 2012 | I9: 2013 | J9: 211629 | K9: Basculante | L9: 25000 | M9: =SUM(L9,J9) -> 236629 | N9: Desativado | P9: Banco Bradesco | Q9: Financeira | R9: Retido
A10: 9 | B10: BAM0G65 | C10: 592303365 | D10: Volvo | E10: VM 270 | F10: Caminhão | G10: Toco | H10: 2013 | I10: 2013 | J10: 0 | K10: Carroceria | L10: 0 | M10: =SUM(L10,J10) -> 0 | N10: Vendido | O10: 110178
A11: 10 | B11: BAM0478 | C11: 996412590 | D11: Volvo | E11: VM 270 | F11: Caminhão | G11: Toco | H11: 2013 | I11: 2013 | J11: 0 | K11: Carroceria | L11: 0 | M11: =SUM(L11,J11) -> 0 | N11: Vendido | O11: 125000
A12: 11 | B12: FIH4496 | C12: 514567759 | D12: Toyota | E12: Etios HB 1.3 Manual | F12: Carro | H12: 2013 | I12: 2013 | J12: 40873 | L12: 0 | M12: =SUM(L12,J12) -> 40873 | N12: Desativado | P12: Nada Consta | Q12: Renajud | R12: Furtado
A13: 12 | B13: GAR0I46 | C13: 1073178045 | D13: Volkswagen | E13: Gol Comfortl. 1.6 | F13: Carro | H13: 2015 | I13: 2016 | J13: 0 | L13: 0 | M13: =SUM(L13,J13) -> 0 | N13: Vendido | O13: 21000
A14: 13 | B14: GHH0155 | C14: 1129174503 | D14: Chevrolet | E14: Prisma Sed. Joy 1.0 | F14: Carro | H14: 2017 | I14: 2018 | J14: 0 | L14: 0 | M14: =SUM(L14,J14) -> 0 | N14: Vendido | O14: 48880
A15: 14 | B15: GEE4D22 | C15: 1129176689 | D15: Chevrolet | E15: Onix Joy 1.0 | F15: Carro | H15: 2017 | I15: 2018 | J15: 0 | L15: 0 | M15: =SUM(L15,J15) -> 0 | N15: Vendido | O15: 27500
A16: 15 | B16: GJJ5485 | C16: 1131048358 | D16: Chevrolet | E16: Onix Joy 1.0 | F16: Carro | H16: 2017 | I16: 2018 | J16: 0 | L16: 0 | M16: =SUM(L16,J16) -> 0 | N16: Vendido | O16: 27500
A17: 16 | B17: GIL6H09 | C17: 1129174651 | D17: Chevrolet | E17: Onix Joy 1.0 | F17: Carro | H17: 2017 | I17: 2018 | J17: 0 | L17: 0 | M17: =SUM(L17,J17) -> 0 | N17: Vendido | O17: 31000
A18: 17 | B18: BQV5264 | C18: 1185265632 | D18: Caterpillar | E18: CAT 416F2 | F18: Retroescavadeira | G18: Máquina | H18: 2018 | I18: 2018 | J18: 180000 | L18: 0 | M18: =SUM(L18,J18) -> 180000 | N18: Frota | P18: Nada Consta | Q18: Renajud | R18: Locado
A19: 18 | B19: ERA6A58 | C19: 1181626088 | D19: Toyota | E19: Hilux SW4 SRV 2.7 Flex | F19: Carro | H19: 2018 | I19: 2019 | J19: 181130 | L19: 0 | M19: =SUM(L19,J19) -> 181130 | N19: Frota | P19: Nada Consta | Q19: Renajud | R19: Locado
A20: 19 | B20: EKJ0028 | C20: 1173726257 | D20: Toyota | E20: Etios 1.3 Aut. | F20: Carro | H20: 2018 | I20: 2019 | J20: 0 | L20: 0 | M20: =SUM(L20,J20) -> 0 | N20: Vendido | O20: 42000
A21: 20 | B21: MAX4116 | C21: 0 | D21: Jcb | E21: 3CX | F21: Retroescavadeira | G21: Máquina | H21: 2020 | I21: 2020 | J21: 230000 | L21: 0 | M21: =SUM(L21,J21) -> 230000 | N21: Frota | P21: Nada Consta | Q21: Nada Consta | R21: Locado
A22: 21 | B22: FZB8D94 | C22: 1232225905 | D22: Mercedes Benz | E22: GLA200FF Advanced | F22: Carro | H22: 2020 | I22: 2020 | J22: 0 | L22: 0 | M22: =SUM(L22,J22) -> 0 | N22: Vendido | O22: 130000
A23: 22 | B23: GIK6G75 | C23: 1234787137 | D23: MIMADO | E23: CARRETA REBOQUE | F23: Reboque | H23: 2020 | I23: 2020 | J23: 0 | L23: 0 | M23: =SUM(L23,J23) -> 0 | N23: Vendido | O23: 11000
A24: 23 | B24: BPB6D57 | C24: 1248267963 | D24: Volkswagen | E24: 24.260 Constellation | F24: Caminhão | G24: Truck | H24: 2020 | I24: 2021 | J24: 0 | K24: Prancha | L24: 0 | M24: =SUM(L24,J24) -> 0 | N24: Vendido | O24: 515000
A25: 24 | B25: DYG5G03 | C25: 1243478176 | D25: Volkswagen | E25: 14.190 Constellation | F25: Caminhão | G25: Toco | H25: 2020 | I25: 2021 | J25: 334654 | K25: Munck | L25: 72500 | M25: =SUM(L25,J25) -> 407154 | N25: Frota | P25: Nada Consta | Q25: Renajud | R25: Quebrado
A26: 25 | B26: CRN8D42 | C26: 1278843024 | D26: Fiat | E26: Fiorino Working | F26: Carro | G26: Utilitário | H26: 2021 | I26: 2021 | J26: 0 | L26: 0 | M26: =SUM(L26,J26) -> 0 | N26: Vendido | O26: 78681
A27: 26 | B27: BYJ1H22 | C27: 1278842958 | D27: Fiat | E27: Fiorino Working | F27: Carro | G27: Utilitário | H27: 2021 | I27: 2021 | J27: 0 | L27: 0 | M27: =SUM(L27,J27) -> 0 | N27: Vendido | O27: 51000
A28: 27 | B28: DRF4J54 | C28: 1278842990 | D28: Fiat | E28: Fiorino Working | F28: Carro | G28: Utilitário | H28: 2021 | I28: 2021 | J28: 0 | L28: 0 | M28: =SUM(L28,J28) -> 0 | N28: Vendido | O28: 51000
A29: 28 | B29: BSY5H86 | C29: 1278439576 | D29: Fiat | E29: Fiorino Working | F29: Carro | G29: Utilitário | H29: 2021 | I29: 2021 | J29: 0 | L29: 0 | M29: =SUM(L29,J29) -> 0 | N29: Vendido | O29: 51000
A30: 29 | B30: BZR7H61 | C30: 1278439584 | D30: Fiat | E30: Fiorino Working | F30: Carro | G30: Utilitário | H30: 2021 | I30: 2021 | J30: 0 | L30: 0 | M30: =SUM(L30,J30) -> 0 | N30: Vendido | O30: 47000
A31: 30 | B31: CUF6C08 | C31: 1278439673 | D31: Fiat | E31: Fiorino Working | F31: Carro | G31: Utilitário | H31: 2021 | I31: 2021 | J31: 0 | L31: 0 | M31: =SUM(L31,J31) -> 0 | N31: Vendido | O31: 51000
A32: 31 | B32: CFZ5I74 | C32: 1278439630 | D32: Fiat | E32: Fiorino Working | F32: Carro | G32: Utilitário | H32: 2021 | I32: 2021 | J32: 0 | L32: 0 | M32: =SUM(L32,J32) -> 0 | N32: Vendido | O32: 51000
A33: 32 | B33: BYQ6A32 | C33: 1278439550 | D33: Fiat | E33: Fiorino Working | F33: Carro | G33: Utilitário | H33: 2021 | I33: 2021 | J33: 0 | L33: 0 | M33: =SUM(L33,J33) -> 0 | N33: Vendido | O33: 51000
A34: 33 | B34: CCF9F13 | C34: 1278439657 | D34: Fiat | E34: Fiorino Working | F34: Carro | G34: Utilitário | H34: 2021 | I34: 2021 | J34: 0 | L34: 0 | M34: =SUM(L34,J34) -> 0 | N34: Vendido | O34: 50000
A35: 34 | B35: EXW7D65 | C35: 1262772548 | D35: Volkswagen | E35: 9.170 Delivery | F35: Caminhão | G35: 3/4 | H35: 2021 | I35: 2022 | J35: 311399 | K35: Basculante | L35: 25000 | M35: =SUM(L35,J35) -> 336399 | N35: Frota | P35: Santander Leasing Reneg | Q35: Financeira | R35: Locado
A36: 35 | B36: DYE3G22 | C36: 1262772343 | D36: Volkswagen | E36: 9.170 Delivery | F36: Caminhão | G36: 3/4 | H36: 2021 | I36: 2022 | J36: 0 | K36: Basculante | L36: 0 | M36: =SUM(L36,J36) -> 0 | N36: Vendido | O36: 240000
A37: 36 | B37: FPY0E65 | C37: 1262772297 | D37: Volkswagen | E37: 9.170 Delivery | F37: Caminhão | G37: 3/4 | H37: 2021 | I37: 2022 | J37: 0 | K37: Carroceria Cabinado | L37: 0 | M37: =SUM(L37,J37) -> 0 | N37: Vendido | O37: 250000
A38: 37 | B38: BWV8F67 | C38: 1262921489 | D38: Volkswagen | E38: 9.170 Delivery | F38: Caminhão | G38: 3/4 | H38: 2021 | I38: 2022 | J38: 0 | K38: Basculante | L38: 0 | M38: =SUM(L38,J38) -> 0 | N38: Vendido | O38: 250000
A39: 38 | B39: CUK9B55 | C39: 1262772424 | D39: Volkswagen | E39: 9.170 Delivery | F39: Caminhão | G39: 3/4 | H39: 2021 | I39: 2022 | J39: 0 | K39: Carroceria Cabinado | L39: 0 | M39: =SUM(L39,J39) -> 0 | N39: Vendido | O39: 240000
A40: 39 | B40: EJX0I24 | C40: 1262921586 | D40: Volkswagen | E40: Express Delivery | F40: Caminhonete | H40: 2021 | I40: 2022 | J40: 234519 | K40: Carroceria Cabinado | L40: 28700 | M40: =SUM(L40,J40) -> 263219 | N40: Frota | P40: Santander Leasing Reneg | Q40: Financeira | R40: Locado
...

Sheet 🏢 CLIENTES
A1: IDCliente | B1: RazaoSocial | C1: CNPJ_CPF | D1: TipoCliente | E1: RamoCliente | F1: ServicoCliente | G1: MunicipioCliente | H1: EstadoCliente | I1: ContatoCliente | J1: EmailCliente | K1: TelefoneCliente | L1: StatusCliente
A2: 1 | B2: Celebre Obras e Servicos LTDA | C2: 12.609.247/0001-99 | D2: PJ | E2: Engenharia | F2: Saneamento | G2: São Paulo | H2: SP | I2: Raul | J2: tatiane@celebrecs.com.br | K2: (11) 2680-7631 | L2: Ativo
A3: 2 | B3: Jwr Construcoes LTDA | C3: 12.616.824/0001-70 | D3: PJ | E3: Engenharia | F3: Saneamento | G3: Barueri | H3: SP | I3: Raul | J3: tatiane@celebrecs.com.br | K3: (11) 3683-1062 | L3: Inativo
A4: 3 | B4: Sialdrill Engenharia e Construcoes LTDA | C4: 08.024.836/0001-38 | D4: PJ | E4: Engenharia | F4: Saneamento | G4: São Paulo | H4: SP | I4: Valdemir | J4: valdemir@sialdrill.com.br | K4: (11) 4440-7920 | L4: Inativo
A5: 4 | B5: Consorcio Gb Osasco Tiete | C5: 44.274.204/0001-96 | D5: PJ | E5: Engenharia | F5: Saneamento | G5: Barueri | H5: SP | I5: Dimitrius | J5: juridico@jobeng.com.br | K5: (11) 2602-2600 | L5: Inativo
A6: 5 | B6: Fbs Adelson Bispo Silva | C6: 37.709.324/0001-03 | D6: PJ | E6: Engenharia | F6: Saneamento | G6: Taboão da Serra | H6: SP | I6: Adelson | J6: fbs.polietileno20@gmail.com | K6: (11) 4139-2718 | L6: Inativo
A7: 6 | B7: Calibr Servicos Tecnicos LTDA | C7: 19.960.028/0001-07 | D7: PJ | E7: Engenharia | F7: Saneamento | G7: São José dos Campos | H7: SP | I7: Steffanie | J7: contato.hjtecnologia@gmail.com | K7: (11) 4764-5616 | L7: Inativo
A8: 7 | B8: Fibertec Engenharia LTDA | C8: 30.828.956/0001-47 | D8: PJ | E8: Engenharia | F8: Fibra | G8: São Paulo | H8: SP | I8: Donizete | J8: contato@fibertecengenharia.com | K8: (11) 3933-2130 | L8: Ativo
A9: 8 | B9: Consorcio Global Franca | C9: 55.070.909/0001-08 | D9: PJ | E9: Engenharia | F9: Saneamento | G9: São José dos Campos | H9: SP | I9: Luis | J9: contato@polemicaconstrutora.com.br | K9: (12) 3941-8555 | L9: Inativo
A10: 9 | B10: Polemica Servicos Basicos LTDA | C10: 61.870.101/0001-08 | D10: PJ | E10: Engenharia | F10: Saneamento | G10: São José dos Campos | H10: SP | I10: Rodrigo | J10: contato@polemicaconstrutora.com.br | K10: (12) 3941-8555 | L10: Ativo
A11: 10 | B11: Rlt Infraestrutura LTDA | C11: 06.949.131/0001-04 | D11: PJ | E11: Engenharia | F11: Saneamento | G11: São Paulo | H11: SP | I11: Jose Carlos | J11: supervisao@rilty.com.br | K11: (11) 2548-0599 | L11: Inativo
A12: 11 | B12: Zigurate Construcao LTDA | C12: 32.836.259/0001-63 | D12: PJ | E12: Engenharia | F12: Saneamento | G12: São Paulo | H12: SP | I12: Juscilana | J12: zigurate@zigurate.eng.br | K12: (11) 2387-1002 | L12: Ativo
A13: 12 | B13: Consorcio Global Franca II | C13: 61.065.464/0001-70 | D13: PJ | E13: Engenharia | F13: Saneamento | G13: São José dos Campos | H13: SP | I13: Ana | J13: contato@polemicaconstrutora.com.br | K13: (12) 3941-8555 | L13: Ativo
... A17: 16 | B17: Angra Construcoes e Saneamento LTDA | C17: 17.598.781/0001-60 | D17: PJ | E17: Engenharia | F17: Saneamento | G17: Barueri | H17: SP | I17: Kelvin | J17: comercial@angraconstrucoes.eng.br | K17: (11) 2970-1020 | L17: Ativo

Sheet 📄 CONTRATOS
A1: IDContrato | B1: IDEmpresa | C1: IDCliente | D1: NomeCliente | E1: OrigemContrato | F1: IDContratoOrigem | G1: ModeloContrato | H1: ResponsavelInterno | I1: CidadeOperacao | J1: EstadoOperacao | K1: DataInicio | L1: DataFimPrevista | M1: DataEncerramento | N1: IDVeiculo | O1: ItensContratados | P1: ValorMensal | Q1: StatusContrato | R1: MotivoEncerramento | S1: DocumentoRede | T1: Observacoes | U1: DiasTotais | V1: Alertas
A2: 1 | B2: 1 | C2: 2 | D2: Jwr Construcoes LTDA | E2: Concessão | G2: Mensal | H2: Antonio Deodato | I2: Campinas | J2: SP | K2: 45127 | L2: 45371 | M2: 45371 | N2: 17;20;24;26;27;28;29;34;39;42;43;45;49 | O2: 22 | P2: 70000 | Q2: Renovado | R2: Prazo | S2: https://tkjgerenciamento.sharepoint.com/:b:/s/REDE2/IQApjW3LPNBbTrl8LXYCvM9BARkL_VSSnOZjC1TZLg_BoLw?e=wZN6r8 | T2: Aditado | U2: =IF(OR(K2="",M2=""),"",M2-K2) -> 244 | V2: =IF(OR(K2="",L2=""),"",IF(Q2="Ativo",L2-TODAY(),""))
A3: 2 | B3: 1 | C3: 15 | D3: Leal Construcao de Redes de Telecomunicacoes LTDA | E3: Concessão | G3: Mensal | H3: Cleibson Leal | I3: São Paulo | J3: SP | K3: 45184 | L3: 45550 | M3: 45199 | N3: 15;38;40;41;44;46 | O3: 7 | P3: 47000 | Q3: Encerrado | R3: Retirada | S3: https://tkjgerenciamento.sharepoint.com/:b:/s/REDE2/IQBV1Tgoq-i6TbFOUgX2pW09AeGNIectu8XKr-C4U8ypzqI?e=NigWUD | T3: Encerrado por falta de pagamento | U3: =IF(OR(K3="",M3=""),"",M3-K3) -> 15 | V3: =IF(OR(K3="",L3=""),"",IF(Q3="Ativo",L3-TODAY(),""))
A4: 3 | B4: 1 | C4: 6 | D4: Calibr Servicos Tecnicos LTDA | E4: Comercial | G4: Mensal | H4: Steffanie Bianca | I4: Otalício Costa | J4: SC | K4: 45307 | L4: 45453 | M4: 45453 | N4: 16;41;47 | O4: 3 | P4: 32900 | Q4: Encerrado | R4: Encerramento de obra | S4: https://tkjgerenciamento.sharepoint.com/:b:/s/REDE2/IQBW2AHAK9DQQIjwr_-GuguKAT1hcvLMcwVsM6-6oJHbsE0?e=ZNoAPs | T4: Finalizado | U4: =IF(OR(K4="",M4=""),"",M4-K4) -> 146 | V4: =IF(OR(K4="",L4=""),"",IF(Q4="Ativo",L4-TODAY(),""))
A5: 4 | B5: 1 | C5: 3 | D5: Sialdrill Engenharia e Construcoes LTDA | E5: Comercial | G5: Mensal | H5: Valdemir Vieira | I5: São Paulo | J5: SP | K5: 45363 | L5: 45547 | M5: 45397 | N5: 23 | O5: 1 | P5: 15000 | Q5: Encerrado | R5: Venda | S5: https://tkjgerenciamento.sharepoint.com/:b:/s/REDE2/IQCuGiHGt9GETpqDu7swSl9kAQjFL2MXKf7GTmBLc9WLuJc?e=AezmTO | T5: Veículo vendido para a locatária BPB7D65 | U5: =IF(OR(K5="",M5=""),"",M5-K5) -> 34 | V5: =IF(OR(K5="",L5=""),"",IF(Q5="Ativo",L5-TODAY(),""))
A6: 5 | B6: 1 | C6: 2 | D6: Jwr Construcoes LTDA | E6: Comercial | F6: 1 | G6: Mensal | H6: Antonio Deodato | I6: Campinas | J6: SP | K6: 45397 | L6: 45397 | M6: 45505 | N6: 17;24;30;32;39;43;45;49 | O6: 12 | P6: 63300 | Q6: Encerrado | R6: Encerramento de obra | S6: https://tkjgerenciamento-my.sharepoint.com/shared?listurl=https%3A%2F%2Ftkjgerenciamento%2Esharepoint%2Ecom%2Fsites%2FREDE2%2FDocumentos%20Compartilhados&viewid=41f98fb8%2D92ae%2D4e59%2D9b01%2D6f58bb773280&id=%2Fsites%2FREDE2%2FDocumentos%20Compartilhados%2FGeneral%2F01%5FGEST%C3%83O%2DPATRIM%C3%94NIOS%2F03%5FContratos%2DLoca%C3%A7%C3%B5es%2FTKJ%2FJWR%20CONSTRU%C3%87%C3%95ES%2FAditivo%2FAditivo02%2DTKJxJWR%2DVeiculos%2D15%2E05%5Fassinado%2Epdf&parent=%2Fsites%2FREDE2%2FDocumentos%20Compartilhados%2FGeneral%2F01%5FGEST%C3%83O%2DPATRIM%C3%94NIOS%2F03%5FContratos%2DLoca%C3%A7%C3%B5es%2FTKJ%2FJWR%20CONSTRU%C3%87%C3%95ES%2FAditivo | T6: Finalizado | U6: =IF(OR(K6="",M6=""),"",M6-K6) -> 108 | V6: =IF(OR(K6="",L6=""),"",IF(Q6="Ativo",L6-TODAY(),""))
A7: 6 | B7: 1 | C7: 1 | D7: Celebre Obras e Servicos LTDA | E7: Comercial | G7: Mensal | H7: Lincoln Ribeiro | I7: São Carlos | J7: SP | K7: 45358 | L7: 45723 | M7: 45723 | N7: 40;44;45;46 | O7: 3 | P7: 20000 | Q7: Renovado | R7: Prazo | S7: https://tkjgerenciamento.sharepoint.com/sites/REDE2/Documentos%20Compartilhados/Forms/AllItems.aspx?id=%2Fsites%2FREDE2%2FDocumentos%20Compartilhados%2FGeneral%2F01%5FGEST%C3%83O%2DPATRIM%C3%94NIOS%2F03%5FContratos%2DLoca%C3%A7%C3%B5es%2FTKJ%2FCELEBRE%20OBRAS%20E%20SERVI%C3%87OS%2FS%C3%A3o%20Carlos%2FContrato%2DCELEBRExTKJ%2DS%2EC%2E%5FCCU5G26%5FFFS0D23%5FDPB8E26%5FCCF9F13%5Fassinado%2Epdf&parent=%2Fsites%2FREDE2%2FDocumentos%20Compartilhados%2FGeneral%2F01%5FGEST%C3%83O%2DPATRIM%C3%94NIOS%2F03%5FContratos%2DLoca%C3%A7%C3%B5es%2FTKJ%2FCELEBRE%20OBRAS%20E%20SERVI%C3%87OS%2FS%C3%A3o%20Carlos&p=true&ga=1 | T7: Saída CCU5G26 em 27/06/24 | U7: =IF(OR(K7="",M7=""),"",M7-K7) -> 365 | V7: =IF(OR(K7="",L7=""),"",IF(Q7="Ativo",L7-TODAY(),""))
A8: 7 | B8: 1 | C8: 2 | D8: Jwr Construcoes LTDA | E8: Comercial | G8: Mensal | H8: Raul Monegalia | I8: Barueri | J8: SP | K8: 45358 | L8: 45723 | M8: 45679 | N8: 33 | O8: 1 | P8: 2900 | Q8: Encerrado | R8: Devolução | S8: https://tkjgerenciamento.sharepoint.com/sites/REDE2/Documentos%20Compartilhados/Forms/AllItems.aspx?id=%2Fsites%2FREDE2%2FDocumentos%20Compartilhados%2FGeneral%2F01%5FGEST%C3%83O%2DPATRIM%C3%94NIOS%2F03%5FContratos%2DLoca%C3%A7%C3%B5es%2FTKJ%2FCELEBRE%20OBRAS%20E%20SERVI%C3%87OS%2FS%C3%A3o%20Carlos%2FContrato%2DCELEBRExTKJ%2DS%2EC%2E%5FCCU5G26%5FFFS0D23%5FDPB8E26%5FCCF9F13%5Fassinado%2Epdf&parent=%2Fsites%2FREDE2%2FDocumentos%20Compartilhados%2FGeneral%2F01%5FGEST%C3%83O%2DPATRIM%C3%94NIOS%2F03%5FContratos%2DLoca%C3%A7%C3%B5es%2FTKJ%2FCELEBRE%20OBRAS%20E%20SERVI%C3%87OS%2FS%C3%A3o%20Carlos&p=true&ga=1 | T8: Locatária devolveu o veículo CCF9F13 | U8: =IF(OR(K8="",M8=""),"",M8-K8) -> 321 | V8: =IF(OR(K8="",L8=""),"",IF(Q8="Ativo",L8-TODAY(),""))
A9: 8 | B9: 1 | C9: 4 | D9: Consorcio Gb Osasco Tiete | E9: Concessão | G9: Mensal | H9: Heitor Defavari | I9: Osasco | J9: SP | K9: 45393 | L9: 45576 | M9: 45597 | N9: 4;6 | O9: 2 | P9: 14000 | Q9: Encerrado | R9: Retirada | S9: https://tkjgerenciamento.sharepoint.com/:b:/s/REDE2/IQCtx1qMqr3YR6_z_jvpo6uSAaiwb1zWxqOhDgRhqojSONw?e=leJ8BQ | T9: Locadora retirou o veículo KJX8J96 | U9: =IF(OR(K9="",M9=""),"",M9-K9) -> 204 | V9: =IF(OR(K9="",L9=""),"",IF(Q9="Ativo",L9-TODAY(),""))
A10: 9 | B10: 1 | C10: 4 | D10: Consorcio Gb Osasco Tiete | E10: Concessão | F10: 8 | G10: Mensal | H10: Andrews Pereira | I10: Osasco | J10: SP | K10: 45393 | L10: 45576 | M10: 45930 | N10: 4;6 | O10: 1 | P10: 9000 | Q10: Encerrado | R10: Devolução | S10: https://tkjgerenciamento.sharepoint.com/:b:/s/REDE2/IQCtx1qMqr3YR6_z_jvpo6uSAaiwb1zWxqOhDgRhqojSONw?e=leJ8BQ | T10: Locatária devolveu o veículo EVF8883 | U10: =IF(OR(K10="",M10=""),"",M10-K10) -> 537 | V10: =IF(OR(K10="",L10=""),"",IF(Q10="Ativo",L10-TODAY(),""))
A11: 10 | B11: 1 | C11: 9 | D11: Polemica Servicos Basicos LTDA | E11: Comercial | G11: Mensal | H11: Lincoln Rennó | I11: Presidente Prudente | J11: SP | K11: 45399 | L11: 45794 | M11: 45778 | N11: 34;42;43 | O11: 3 | P11: 23200 | Q11: Renovado | R11: Prazo | S11: https://tkjgerenciamento.sharepoint.com/:b:/s/REDE2/IQBbFmsH7Y-cSY9ZAs-tj0mqAfwynEe4Cu8D8oS1HxW_Q7Q?e=PXXqot | T11: Aditado | U11: =IF(OR(K11="",M11=""),"",M11-K11) -> 379 | V11: =IF(OR(K11="",L11=""),"",IF(Q11="Ativo",L11-TODAY(),""))
A12: 11 | B12: 1 | C12: 11 | D12: Zigurate Construcao LTDA | E12: Comercial | G12: Mensal | H12: Juscilana Carvalho | I12: Suzano | J12: SP | K12: 45414 | L12: 45779 | M12: 45869 | N12: 9;10 | O12: 1 | P12: 14000 | Q12: Encerrado | R12: Devolução | S12: https://tkjgerenciamento.sharepoint.com/:b:/s/REDE2/IQAPOjMBC39OQLgkIfslRkboAe9Uu0KK1RX6S1R2vKrUsI8?e=opzCkH | T12: Locatária devolveu o veículo | U12: =IF(OR(K12="",M12=""),"",M12-K12) -> 455 | V12: =IF(OR(K12="",L12=""),"",IF(Q12="Ativo",L12-TODAY(),""))
A13: 12 | B13: 1 | C13: 1 | D13: Celebre Obras e Servicos LTDA | E13: Comercial | G13: Mensal | H13: Raul Monegalia | I13: São Paulo | J13: SP | K13: 45442 | L13: 45807 | M13: 45534 | N13: 17 | O13: 1 | P13: 12000 | Q13: Encerrado | R13: Devolução | S13: https://tkjgerenciamento.sharepoint.com/:b:/s/REDE2/IQDKeaNq1ZH8Q77jcA_hEVNnAQ-RTufc6ou9xHaSW3yAAW8?e=0nswPE | T13: Locatária devolveu a máquina | U13: =IF(OR(K13="",M13=""),"",M13-K13) -> 92 | V13: =IF(OR(K13="",L13=""),"",IF(Q13="Ativo",L13-TODAY(),""))
A14: 13 | B14: 1 | C14: 9 | D14: Polemica Servicos Basicos LTDA | E14: Comercial | G14: Mensal | H14: Rodrigo Rodrigues | I14: Presidente Prudente | J14: SP | K14: 45488 | L14: 45853 | M14: 45853 | N14: 46 | O14: 1 | P14: 7100 | Q14: Renovado | R14: Prazo | S14: https://tkjgerenciamento.sharepoint.com/:b:/s/REDE2/IQCI4mduATVxR5T4PXPy38SpAfspslgu4zRrBr4VZShvmks?e=dqj0gS | T14: Aditado | U14: =IF(OR(K14="",M14=""),"",M14-K14) -> 365 | V14: =IF(OR(K14="",L14=""),"",IF(Q14="Ativo",L14-TODAY(),""))
A15: 14 | B15: 1 | C15: 11 | D15: Zigurate Construcao LTDA | E15: Comercial | G15: Mensal | H15: Juscilana Carvalho | I15: Suzano | J15: SP | K15: 45506 | L15: 45871 | M15: 45870 | N15: 24 | O15: 1 | P15: 12000 | Q15: Renovado | R15: Migração de locadora | S15: https://tkjgerenciamento.sharepoint.com/:b:/s/REDE2/IQAww3mRUnL5QJV2chuirBhpAcn_yjT9gdlaO0u4lS23krE?e=iTa8Ac | T15: Aditado via Landkraft | U15: =IF(OR(K15="",M15=""),"",M15-K15) -> 364 | V15: =IF(OR(K15="",L15=""),"",IF(Q15="Ativo",L15-TODAY(),""))
A16: 15 | B16: 1 | C16: 1 | D16: Celebre Obras e Servicos LTDA | E16: Comercial | G16: Mensal | H16: Luis Lacerda | I16: Mogi das Cruzes | J16: SP | K16: 45509 | L16: 45580 | M16: 45580 | N16: 39;41 | O16: 2 | P16: 16000 | Q16: Renovado | R16: Prazo | S16: https://tkjgerenciamento.sharepoint.com/:b:/s/REDE2/IQCWY2mRzYvNRarhGyJqpHzuAZ-QvgBI_avNUjpsUGUp5oc?e=VYgomG | T16: Aditado | U16: =IF(OR(K16="",M16=""),"",M16-K16) -> 71 | V16: =IF(OR(K16="",L16=""),"",IF(Q16="Ativo",L16-TODAY(),""))
A17: 16 | B17: 1 | C17: 7 | D17: Fibertec Engenharia LTDA | E17: Comercial | G17: Mensal | H17: Donizete Pereira | I17: Osasco | J17: SP | K17: 45532 | L17: 45897 | M17: 45897 | N17: 47 | O17: 1 | P17: 15000 | Q17: Renovado | R17: Prazo | S17: https://tkjgerenciamento.sharepoint.com/:b:/s/REDE2/IQAayBdoruDnRJbTXZW2mqBbAUsP3vXUpZDitUPwaZYZSOw?e=TpyfK3 | T17: Aditado via Landkraft | U17: =IF(OR(K17="",M17=""),"",M17-K17) -> 365 | V17: =IF(OR(K17="",L17=""),"",IF(Q17="Ativo",L17-TODAY(),""))
A18: 17 | B18: 1 | C18: 11 | D18: Zigurate Construcao LTDA | E18: Comercial | G18: Mensal | H18: Juscilana Carvalho | I18: Suzano | J18: SP | K18: 45534 | L18: 45899 | M18: 45899 | N18: 17 | O18: 1 | P18: 10000 | Q18: Renovado | R18: Migração de locadora | S18: https://tkjgerenciamento.sharepoint.com/:b:/s/REDE2/IQDpGXpjWA1BTrgnfwlXIFz_ARb8lqqf8OGmYgG-2vJjB8g?e=aqP7Iz | T18: Aditado via Landkraft | U18: =IF(OR(K18="",M18=""),"",M18-K18) -> 365 | V18: =IF(OR(K18="",L18=""),"",IF(Q18="Ativo",L18-TODAY(),""))
A19: 18 | B19: 1 | C19: 10 | D19: Rlt Infraestrutura LTDA | E19: Comercial | G19: Mensal | H19: Eduardo Marques | I19: Joinville | J19: SC | K19: 45534 | L19: 45717 | M19: 45574 | N19: 20 | O19: 1 | P19: 12000 | Q19: Encerrado | R19: Inadimplência | S19: https://tkjgerenciamento.sharepoint.com/:b:/s/REDE2/IQArCx9Je28HSYWk9TxbfxZBAUbPa9sKGKWCeOkouslX0pk?e=as68hL | T19: Locadora retirou a máquina | U19: =IF(OR(K19="",M19=""),"",M19-K19) -> 40 | V19: =IF(OR(K19="",L19=""),"",IF(Q19="Ativo",L19-TODAY(),""))
A20: 19 | B20: 1 | C20: 7 | D20: Fibertec Engenharia LTDA | E20: Comercial | G20: Mensal | H20: Donizete Pereira | I20: Resende | J20: RJ | K20: 45603 | L20: 45784 | M20: 45724 | N20: 6 | O20: 1 | P20: 12000 | Q20: Encerrado | R20: Devolução | S20: https://tkjgerenciamento.sharepoint.com/:b:/s/REDE2/IQBBe_nRyKeJS6FQZvU1lWiAAQDZlK7P7Yku9Q-veN0WgtQ?e=wzKal8 | T20: Locadora devolveu o veículo | U20: =IF(OR(K20="",M20=""),"",M20-K20) -> 121
A21: 20 | B21: 1 | C21: 8 | D21: Consorcio Global Franca | E21: Comercial | G21: Mensal | H21: Luis Gustavo | I21: Franca | J21: SP | K21: 45576 | L21: 46306 | M21: 45901 | N21: 20 | O21: 1 | P21: 12000 | Q21: Encerrado | R21: Migração de empresas | S21: Contrato-C.G.FRANCAxTKJ_JCB3cx_assinado | T21: Transição de empresas | U21: =IF(OR(K21="",M21=""),"",M21-K21) -> 325 | V21: =IF(OR(K21="",L21=""),"",IF(Q21="Ativo",L21-TODAY(),""))
A22: 21 | B22: 1 | C22: 1 | D22: Celebre Obras e Servicos LTDA | E22: Comercial | F22: 15 | G22: Mensal | H22: Luis Lacerda | I22: Mogi das Cruzes | J22: SP | K22: 45580 | L22: 45703 | M22: 45703 | N22: 39;41 | O22: 2 | P22: 16000 | Q22: Renovado | R22: Prazo | S22: Aditivo1-1224_Contrato-CELEBRExTKJ-DLG0G92_EJX0I24 | T22: Aditado | U22: =IF(OR(K22="",M22=""),"",M22-K22) -> 123 | V22: =IF(OR(K22="",L22=""),"",IF(Q22="Ativo",L22-TODAY(),""))
A23: 22 | B23: 1 | C23: 1 | D23: Celebre Obras e Servicos LTDA | E23: Comercial | F23: 15 | G23: Mensal | H23: Luis Lacerda | I23: Mogi das Cruzes | J23: SP | K23: 45703 | L23: 45823 | M23: 45976 | N23: 39;41 | O23: 2 | P23: 17000 | Q23: Renovado | R23: Prazo | S23: Aditivo_2-0325-CELEBRExTKJ_DLG0D92-EJX0I24 | T23: Aditado | U23: =IF(OR(K23="",M23=""),"",M23-K23) -> 273 | V23: =IF(OR(K23="",L23=""),"",IF(Q23="Ativo",L23-TODAY(),""))
A24: 23 | B24: 1 | C24: 1 | D24: Celebre Obras e Servicos LTDA | E24: Comercial | F24: 6 | G24: Mensal | H24: Lincoln Ribeiro | I24: São Carlos | J24: SP | K24: 45748 | L24: 46113 | M24: 46113 | N24: 40;44;45 | O24: 3 | P24: 21550 | Q24: Renovado | R24: Prazo | S24: Aditivo_1-0325-CELEBRExTKJ_S.C. | T24: Aguardando assinatura de aditivo | U24: =IF(OR(K24="",M24=""),"",M24-K24) -> 365 | V24: =IF(OR(K24="",L24=""),"",IF(Q24="Ativo",L24-TODAY(),""))
A25: 24 | B25: 1 | C25: 9 | D25: Polemica Servicos Basicos LTDA | E25: Comercial | F25: 10 | G25: Mensal | H25: Rodrigo Rodrigues | I25: Presidente Prudente | J25: SP | K25: 45778 | L25: 46143 | M25: 45901 | N25: 34;42;43 | O25: 3 | P25: 25520 | Q25: Renovado | R25: Migração de locadora | S25: Aditivo2025-TKJxPolemica-CSU3F94_BSX5H07_EXW7D56_assinado.pdf | T25: Transferido para Landkraft | U25: =IF(OR(K25="",M25=""),"",M25-K25) -> 123 | V25: =IF(OR(K25="",L25=""),"",IF(Q25="Ativo",L25-TODAY(),""))
A26: 25 | B26: 1 | C26: 9 | D26: Polemica Servicos Basicos LTDA | E26: Comercial | F26: 13 | G26: Mensal | H26: Rodrigo Rodrigues | I26: Presidente Prudente | J26: SP | K26: 45853 | L26: 46143 | M26: 45901 | N26: 46 | O26: 1 | P26: 7810 | Q26: Renovado | R26: Migração de locadora | S26: Aditivo_1-0725-TKJxPOLÊMICA_CCU5G26 | T26: Transferido para Landkraft | U26: =IF(OR(K26="",M26=""),"",M26-K26) -> 48 | V26: =IF(OR(K26="",L26=""),"",IF(Q26="Ativo",L26-TODAY(),""))
A27: 26 | B27: 3 | C27: 11 | D27: Zigurate Construcao LTDA | E27: Comercial | F27: 14;17 | G27: Mensal | H27: Juscilana Carvalho | I27: Suzano | J27: SP | K27: 45870 | L27: 46235 | N27: 17;24 | O27: 2 | P27: 27500 | Q27: Ativo | S27: LANDKRAFTxZIGURATE_08.2025-Assinado | T27: Em andamento com valor atualizado | U27: =IF(OR(K27="",M27=""),"",M27-K27) | V27: =IF(OR(K27="",L27=""),"",IF(Q27="Ativo",L27-TODAY(),"")) -> 83
A28: 27 | B28: 3 | C28: 7 | D28: Fibertec Engenharia LTDA | E28: Comercial | F28: 16 | G28: Mensal | H28: Donizete Pereira | I28: Osasco | J28: SP | K28: 45897 | L28: 46022 | M28: 46022 | N28: 47 | O28: 1 | P28: 18500 | Q28: Renovado | R28: Prazo | S28: LANDKRAFTxFIBERTEC_08.25-Assinado | T28: Aguardando assinatura de aditivo | U28: =IF(OR(K28="",M28=""),"",M28-K28) -> 125 | V28: =IF(OR(K28="",L28=""),"",IF(Q28="Ativo",L28-TODAY(),""))
A29: 28 | B29: 3 | C29: 12 | D29: Consorcio Global Franca II | E29: Comercial | F29: 19 | G29: Mensal | H29: Luis Gustavo | I29: Franca | J29: SP | K29: 45901 | L29: 46266 | N29: 20 | O29: 1 | P29: 12550 | Q29: Ativo | S29: LANDKRAFTxC.G.F.II_09.2025_assinado | T29: Em andamento com valor atualizado | U29: =IF(OR(K29="",M29=""),"",M29-K29) | V29: =IF(OR(K29="",L29=""),"",IF(Q29="Ativo",L29-TODAY(),"")) -> 114
A30: 29 | B30: 3 | C30: 9 | D30: Polemica Servicos Basicos LTDA | E30: Comercial | F30: 10;13 | G30: Mensal | H30: Rodrigo Rodrigues | I30: Presidente Prudente | J30: SP | K30: 45901 | L30: 46143 | M30: 46143 | N30: 34;42;43;46 | O30: 4 | P30: 33330 | Q30: Renovado | S30: LANDKRAFTxPOLÊMICA_09.25 | T30: Em andamento com valor atualizado | U30: =IF(OR(K30="",M30=""),"",M30-K30) -> 242 | V30: =IF(OR(K30="",L30=""),"",IF(Q30="Ativo",L30-TODAY(),""))
A31: 30 | B31: 1 | C31: 13 | D31: Consorcio Manutencao Guarapiranga | E31: Comercial | G31: Mensal | H31: Georlando Maciel | I31: Itapecirica da Serra | J31: SP | K31: 45968 | L31: 46149 | M31: 45994 | N31: 6 | O31: 1 | P31: 14000 | Q31: Encerrado | R31: Retirada | S31: TKJxC.M.G._11.2025v2 | T31: Locadora retirou o veículo | U31: =IF(OR(K31="",M31=""),"",M31-K31) -> 26 | V31: =IF(OR(K31="",L31=""),"",IF(Q31="Ativo",L31-TODAY(),""))
A32: 31 | B32: 1 | C32: 1 | D32: Celebre Obras e Servicos LTDA | E32: Comercial | F32: 15 | G32: Mensal | H32: Luis Lacerda | I32: Mogi das Cruzes | J32: SP | K32: 45976 | L32: 46157 | M32: 46077 | N32: 39;41 | O32: 2 | P32: 22100 | Q32: Encerrado | R32: Devolução | S32: Aditivo3-0126_Contrato-CELEBRExTKJ-DLG0G92_EJX0I24-N.Assinado | T32: Valor praticado porém, aditivo sem assinatura | U32: =IF(OR(K32="",M32=""),"",M32-K32) -> 101 | V32: =IF(OR(K32="",L32=""),"",IF(Q32="Ativo",L32-TODAY(),""))
A33: 32 | B33: 1 | C33: 16 | D33: Angra Construcoes e Saneamento LTDA | E33: Comercial | G33: Mensal | H33: Lincoln Ribeiro | I33: São Carlos | J33: SP | K33: 46062 | L33: 46243 | N33: 39 | O33: 1 | P33: 9500 | Q33: Ativo | S33: Contrato_TKJxAngra-S.C._Assinado | T33: Pagamento atualizado para dia 30 | U33: =IF(OR(K33="",M33=""),"",M33-K33) | V33: =IF(OR(K33="",L33=""),"",IF(Q33="Ativo",L33-TODAY(),"")) -> 91
A34: 33 | B34: 3 | C34: 7 | D34: Fibertec Engenharia LTDA | E34: Comercial | F34: 16 | G34: Mensal | H34: Donizete Pereira | I34: Osasco | J34: SP | K34: 46082 | L34: 46447 | N34: 47 | O34: 1 | P34: 20550 | Q34: Ativo | S34: Aditivo-LANDKRAFTxFIBERTEC_03.2026 | T34: Aguardando assinatura | U34: =IF(OR(K34="",M34=""),"",M34-K34) | V34: =IF(OR(K34="",L34=""),"",IF(Q34="Ativo",L34-TODAY(),"")) -> 295
A35: 34 | B35: 3 | C35: 9 | D35: Polemica Servicos Basicos LTDA | E35: Comercial | G35: Mensal | H35: Rodrigo Rodrigues | I35: Presidente Prudente | J35: SP | K35: 46083 | L35: 46448 | N35: 41 | O35: 1 | P35: 9550 | Q35: Ativo | S35: Contrato_LandkraftXPolêmica-02.2026 | T35: Chegada em 05/03/2026 | U35: =IF(OR(K35="",M35=""),"",M35-K35) | V35: =IF(OR(K35="",L35=""),"",IF(Q35="Ativo",L35-TODAY(),"")) -> 296
A36: 35 | B36: 1 | C36: 1 | D36: Celebre Obras e Servicos LTDA | E36: Comercial | F36: 6 | G36: Mensal | H36: Lincoln Ribeiro | I36: São Carlos | J36: SP | K36: 46088 | L36: 46453 | N36: 40;44;45 | O36: 3 | P36: 25500 | Q36: Ativo | S36: Aditivo_2-0326-CELEBRExTKJ_S.C. | T36: Aguardando assinatura | U36: =IF(OR(K36="",M36=""),"",M36-K36) | V36: =IF(OR(K36="",L36=""),"",IF(Q36="Ativo",L36-TODAY(),"")) -> 301
A37: 36 | B37: 3 | C37: 9 | D37: Polemica Servicos Basicos LTDA | E37: Comercial | F37: 10;13 | G37: Mensal | H37: Rodrigo Rodrigues | I37: Presidente Prudente | J37: SP | K37: 46143 | L37: 46508 | N37: 34;42;43;46 | O37: 4 | P37: 38000 | Q37: Ativo | S37: Aditivo1_LandkraftXPolêmica-04.2026 | T37: Aguardando encerramento contrato 26 | U37: =IF(OR(K37="",M37=""),"",M37-K37) | V37: =IF(OR(K37="",L37=""),"",IF(Q37="Ativo",L37-TODAY(),"")) -> 356

Sheet 💰 FAT_UNITARIO
A1: IDFatUnitario | B1: Mes | C1: IDVeiculo | D1: IDEmpresa | E1: Placa | F1: Modelo | G1: Implemento | H1: IDContrato | I1: Diaria | J1: Trabalhado | K1: Parado | L1: Medicao | M1: Contrato
A2: 1 | B2: 45658 | C2: 24 | D2: 1 | E2: DYG5G03 | F2: VW 14-190 | G2: Munck | H2: 11 | I2: =12000/30 -> 400 | J2: 30 | K2: =IF(J2="", 0, 30 - J2) -> 0 | L2: =I2*J2 -> 12000 | M2: Suzano
A3: 2 | B3: 45658 | C3: 17 | D3: 1 | E3: BQV5264 | F3: CAT 416f2 | G3: Retroescavadeira | H3: 17 | I3: =10000/30 -> 333.33333 | J3: 30 | K3: =IF(J3="", 0, 30 - J3) -> 0 | L3: =I3*J3 -> 10000 | M3: Suzano
A4: 3 | B4: 45658 | C4: 20 | D4: 1 | E4: MAX4116 | F4: JCB 3CX | G4: Retroescavadeira | H4: 20 | I4: =12000/30 -> 400 | J4: 30 | K4: =IF(J4="", 0, 30 - J4) -> 0 | L4: =I4*J4 -> 12000 | M4: Franca
A5: 4 | B5: 45658 | C5: 43 | D5: 1 | E5: CSU3F94 | F5: VW EXPRESS | G5: Carroceria | H5: 10 | I5: =7100/30 -> 236.66667 | J5: 30 | K5: =IF(J5="", 0, 30 - J5) -> 0 | L5: =I5*J5 -> 7100 | M5: Presidente Prudente
A6: 5 | B6: 45658 | C6: 42 | D6: 1 | E6: BSX5H07 | F6: VW EXPRESS | G6: Carroceria | H6: 10 | I6: =7100/30 -> 236.66667 | J6: 30 | K6: =IF(J6="", 0, 30 - J6) -> 0 | L6: =I6*J6 -> 7100 | M6: Presidente Prudente
A7: 6 | B7: 45658 | C7: 46 | D7: 1 | E7: CCU5G26 | F7: VW EXPRESS | G7: Carroceria | H7: 13 | I7: =7100/30 -> 236.66667 | J7: 30 | K7: =IF(J7="", 0, 30 - J7) -> 0 | L7: =I7*J7 -> 7100 | M7: Presidente Prudente
A8: 7 | B8: 45658 | C8: 34 | D8: 1 | E8: EXW7D65 | F8: VW 9-170 | G8: Caçamba | H8: 10 | I8: =9000/30 -> 300 | J8: 30 | K8: =IF(J8="", 0, 30 - J8) -> 0 | L8: =I8*J8 -> 9000 | M8: Presidente Prudente
A9: 8 | B9: 45658 | C9: 45 | D9: 1 | E9: EMN8B51 | F9: VW EXPRESS | G9: Carroceria | H9: 6 | I9: =6500/30 -> 216.66667 | J9: 30 | K9: =IF(J9="", 0, 30 - J9) -> 0 | L9: =I9*J9 -> 6500 | M9: São Carlos
A10: 9 | B10: 45658 | C10: 44 | D10: 1 | E10: FFS0D23 | F10: VW EXPRESS | G10: Carroceria | H10: 6 | I10: =6500/30 -> 216.66667 | J10: 30 | K10: =IF(J10="", 0, 30 - J10) -> 0 | L10: =I10*J10 -> 6500 | M10: São Carlos
A11: 10 | B11: 45658 | C11: 40 | D11: 1 | E11: DPB8E26 | F11: VW EXPRESS | G11: Carroceria Cabinado | H11: 6 | I11: =7000/30 -> 233.33333 | J11: 30 | K11: =IF(J11="", 0, 30 - J11) -> 0 | L11: =I11*J11 -> 7000 | M11: São Carlos
A12: 11 | B12: 45658 | C12: 41 | D12: 1 | E12: DLG0D92 | F12: VW EXPRESS | G12: Carroceria Cabinado | H12: 21 | I12: =8000/30 -> 266.66667 | J12: 28 | K12: =IF(J12="", 0, 30 - J12) -> 2 | L12: =I12*J12 -> 7466.6667 | M12: Mogi das Cruzes
A13: 12 | B13: 45658 | C13: 39 | D13: 1 | E13: EJX0I24 | F13: VW EXPRESS | G13: Carroceria Cabinado | H13: 21 | I13: =8000/30 -> 266.66667 | J13: 30 | K13: =IF(J13="", 0, 30 - J13) -> 0 | L13: =I13*J13 -> 8000 | M13: Mogi das Cruzes
A14: 13 | B14: 45658 | C14: 47 | D14: 1 | E14: CUG4B86 | F14: MB ATEGO | G14: Prancha Hidráulica | H14: 16 | I14: =15000/30 -> 500 | J14: 30 | K14: =IF(J14="", 0, 30 - J14) -> 0 | L14: =I14*J14 -> 15000 | M14: Osasco
A15: 14 | B15: 45658 | C15: 33 | D15: 1 | E15: CCF9F13 | F15: FIAT FIORINO | G15: Furgão | H15: 7 | I15: =2900/30 -> 96.666667 | J15: 22 | K15: =IF(J15="", 0, 30 - J15) -> 8 | L15: =I15*J15 -> 2126.6667 | M15: Barueri
A16: 15 | B16: 45658 | C16: 6 | D16: 1 | E16: EVF8I83 | F16: VW 13-180 | G16: Munck | H16: 19 | I16: =12000/30 -> 400 | J16: 22 | K16: =IF(J16="", 0, 30 - J16) -> 8 | L16: =I16*J16 -> 8800 | M16: Osasco
A17: 16 | B17: 45658 | C17: 7 | D17: 1 | E17: EUK4135 | F17: VW 9-150 | G17: Chassi | I17: 0 | J17: 0 | K17: =IF(J17="", 0, 30 - J17) -> 30 | L17: =I17*J17 -> 0 | M17: Parado
A18: 18 | B18: 45689 | C18: 24 | D18: 1 | E18: DYG5G03 | F18: VW 14-190 | G18: Munck | H18: 11 | I18: =12000/30 -> 400 | J18: 30 | K18: =IF(J18="", 0, 30 - J18) -> 0 | L18: =I18*J18 -> 12000 | M18: Suzano
A19: 19 | B19: 45689 | C19: 17 | D19: 1 | E19: BQV5264 | F19: CAT 416f2 | G19: Retroescavadeira | H19: 17 | I19: =10000/30 -> 333.33333 | J19: 30 | K19: =IF(J19="", 0, 30 - J19) -> 0 | L19: =I19*J19 -> 10000 | M19: Suzano
A20: 20 | B20: 45689 | C20: 20 | D20: 1 | E20: MAX4116 | F20: JCB 3CX | G20: Retroescavadeira | H20: 20 | I20: =12000/30 -> 400 | J20: 28 | K20: =IF(J20="", 0, 30 - J20) -> 2 | L20: 11100 | M20: Franca
A21: 21 | B21: 45689 | C21: 43 | D21: 1 | E21: CSU3F94 | F21: VW EXPRESS | G21: Carroceria | H21: 10 | I21: =7100/30 -> 236.66667 | J21: 30 | K21: =IF(J21="", 0, 30 - J21) -> 0 | L21: =I21*J21 -> 7100 | M21: Presidente Prudente
A22: 22 | B22: 45689 | C22: 42 | D22: 1 | E22: BSX5H07 | F22: VW EXPRESS | G22: Carroceria | H22: 10 | I22: =7100/30 -> 236.66667 | J22: 30 | K22: =IF(J22="", 0, 30 - J22) -> 0 | L22: =I22*J22 -> 7100 | M22: Presidente Prudente
A23: 23 | B23: 45689 | C23: 46 | D23: 1 | E23: CCU5G26 | F23: VW EXPRESS | G23: Carroceria | H23: 13 | I23: =7100/30 -> 236.66667 | J23: 30 | K23: =IF(J23="", 0, 30 - J23) -> 0 | L23: =I23*J23 -> 7100 | M23: Presidente Prudente
A24: 24 | B24: 45689 | C24: 34 | D24: 1 | E24: EXW7D65 | F24: VW 9-170 | G24: Caçamba | H24: 10 | I24: =9000/30 -> 300 | J24: 30 | K24: =IF(J24="", 0, 30 - J24) -> 0 | L24: =I24*J24 -> 9000 | M24: Presidente Prudente
A25: 25 | B25: 45689 | C25: 45 | D25: 1 | E25: EMN8B51 | F25: VW EXPRESS | G25: Carroceria | H25: 6 | I25: =6500/30 -> 216.66667 | J25: 30 | K25: =IF(J25="", 0, 30 - J25) -> 0 | L25: =I25*J25 -> 6500 | M25: São Carlos
A26: 26 | B26: 45689 | C26: 44 | D26: 1 | E26: FFS0D23 | F26: VW EXPRESS | G26: Carroceria | H26: 6 | I26: =6500/30 -> 216.66667 | J26: 30 | K26: =IF(J26="", 0, 30 - J26) -> 0 | L26: =I26*J26 -> 6500 | M26: São Carlos
A27: 27 | B27: 45689 | C27: 40 | D27: 1 | E27: DPB8E26 | F27: VW EXPRESS | G27: Carroceria Cabinado | H27: 6 | I27: =7000/30 -> 233.33333 | J27: 30 | K27: =IF(J27="", 0, 30 - J27) -> 0 | L27: =I27*J27 -> 7000 | M27: São Carlos
A28: 28 | B28: 45689 | C28: 41 | D28: 1 | E28: DLG0D92 | F28: VW EXPRESS | G28: Carroceria Cabinado | H28: 21 | I28: =8000/30 -> 266.66667 | J28: 30 | K28: =IF(J28="", 0, 30 - J28) -> 0 | L28: =I28*J28 -> 8000 | M28: Mogi das Cruzes
A29: 29 | B29: 45689 | C29: 39 | D29: 1 | E29: EJX0I24 | F29: VW EXPRESS | G29: Carroceria Cabinado | H29: 21 | I29: =8000/30 -> 266.66667 | J29: 30 | K29: =IF(J29="", 0, 30 - J29) -> 0 | L29: =I29*J29 -> 8000 | M29: Mogi das Cruzes
A30: 30 | B30: 45689 | C30: 47 | D30: 1 | E30: CUG4B86 | F30: MB ATEGO | G30: Prancha Hidráulica | H30: 16 | I30: =15000/30 -> 500 | J30: 30 | K30: =IF(J30="", 0, 30 - J30) -> 0 | L30: =I30*J30 -> 15000 | M30: Osasco
A31: 31 | B31: 45689 | C31: 6 | D31: 1 | E31: EVF8I83 | F31: VW 13-180 | G31: Munck | H31: 19 | I31: =12000/30 -> 400 | J31: 30 | K31: =IF(J31="", 0, 30 - J31) -> 0 | L31: =I31*J31 -> 12000 | M31: Osasco
A32: 32 | B32: 45689 | C32: 7 | D32: 1 | E32: EUK4135 | F32: VW 9-150 | G32: Chassi | I32: 0 | J32: 0 | K32: =IF(J32="", 0, 30 - J32) -> 30 | L32: =I32*J32 -> 0 | M32: Parado
A33: 33 | B33: 45717 | C33: 24 | D33: 1 | E33: DYG5G03 | F33: VW 14-190 | G33: Munck | H33: 11 | I33: =12000/30 -> 400 | J33: 30 | K33: =IF(J33="", 0, 30 - J33) -> 0 | L33: =I33*J33 -> 12000 | M33: Suzano
A34: 34 | B34: 45717 | C34: 17 | D34: 1 | E34: BQV5264 | F34: CAT 416f2 | G34: Retroescavadeira | H34: 17 | I34: =10000/30 -> 333.33333 | J34: 30 | K34: =IF(J34="", 0, 30 - J34) -> 0 | L34: =I34*J34 -> 10000 | M34: Suzano
A35: 35 | B35: 45717 | C35: 20 | D35: 1 | E35: MAX4116 | F35: JCB 3CX | G35: Retroescavadeira | H35: 20 | I35: =12000/30 -> 400 | J35: 30 | K35: =IF(J35="", 0, 30 - J35) -> 0 | L35: =I35*J35 -> 12000 | M35: Franca
A36: 36 | B36: 45717 | C36: 43 | D36: 1 | E36: CSU3F94 | F36: VW EXPRESS | G36: Carroceria | H36: 10 | I36: =7100/30 -> 236.66667 | J36: 30 | K36: =IF(J36="", 0, 30 - J36) -> 0 | L36: =I36*J36 -> 7100 | M36: Presidente Prudente
A37: 37 | B37: 45717 | C37: 42 | D37: 1 | E37: BSX5H07 | F37: VW EXPRESS | G37: Carroceria | H37: 10 | I37: =7100/30 -> 236.66667 | J37: 30 | K37: =IF(J37="", 0, 30 - J37) -> 0 | L37: =I37*J37 -> 7100 | M37: Presidente Prudente
A38: 38 | B38: 45717 | C38: 46 | D38: 1 | E38: CCU5G26 | F38: VW EXPRESS | G38: Carroceria | H38: 13 | I38: =7100/30 -> 236.66667 | J38: 30 | K38: =IF(J38="", 0, 30 - J38) -> 0 | L38: =I38*J38 -> 7100 | M38: Presidente Prudente
A39: 39 | B39: 45717 | C39: 34 | D39: 1 | E39: EXW7D65 | F39: VW 9-170 | G39: Caçamba | H39: 10 | I39: =9000/30 -> 300 | J39: 30 | K39: =IF(J39="", 0, 30 - J39) -> 0 | L39: =I39*J39 -> 9000 | M39: Presidente Prudente
A40: 40 | B40: 45717 | C40: 45 | D40: 1 | E40: EMN8B51 | F40: VW EXPRESS | G40: Carroceria | H40: 6 | I40: =6500/30 -> 216.66667 | J40: 30 | K40: =IF(J40="", 0, 30 - J40) -> 0 | L40: =I40*J40 -> 6500 | M40: São Carlos
...

Sheet 🧾 FATURAMENTO
A1: IDFatura | B1: Medicao | C1: IDEmpresa | D1: IDContrato | E1: IDCliente | F1: Fatura | G1: Emissão | H1: Vencimento | I1: Empresa | J1: ValorLocacoes | K1: DataEntrada | L1: ValorRecebido | M1: Encargos | N1: FormaRecebimento | O1: StatusRecebimento | P1: DocumentoRede
A2: 1 | B2: 45627 | C2: 1 | D2: 10;13 | E2: 9 | F2: 256 | G2: 45659 | H2: 45663 | I2: =IF(E2="","",_xlfn.XLOOKUP(E2,'🏢 CLIENTES'!A:A,'🏢 CLIENTES'!B:B,"")) -> Polemica Servicos Basicos LTDA | J2: 30300 | K2: 45663 | L2: 30300 | M2: =IF(OR(L2=0,L2=""),0,L2-J2) -> 0 | N2: Boleto | O2: Recebido
A3: 2 | B3: 45627 | C3: 1 | D3: 20 | E3: 8 | F3: 257 | G3: 45659 | H3: 45663 | I3: =IF(E3="","",_xlfn.XLOOKUP(E3,'🏢 CLIENTES'!A:A,'🏢 CLIENTES'!B:B,"")) -> Consorcio Global Franca | J3: 12000 | K3: 45663 | L3: 12000 | M3: =IF(OR(L3=0,L3=""),0,L3-J3) -> 0 | N3: Boleto | O3: Recebido
A4: 4 | B4: 45627 | C4: 1 | D4: 14;17 | E4: 11 | F4: 255 | G4: 45659 | H4: 45663 | I4: =IF(E4="","",_xlfn.XLOOKUP(E4,'🏢 CLIENTES'!A:A,'🏢 CLIENTES'!B:B,"")) -> Zigurate Construcao LTDA | J4: 22000 | K4: 45678 | L4: 23100 | M4: =IF(OR(L4=0,L4=""),0,L4-J4) -> 1100 | N4: Pix | O4: Recebido
A5: 6 | B5: 45627 | C5: 1 | D5: 7 | E5: 2 | F5: 260 | G5: 45659 | H5: 45663 | I5: =IF(E5="","",_xlfn.XLOOKUP(E5,'🏢 CLIENTES'!A:A,'🏢 CLIENTES'!B:B,"")) -> Jwr Construcoes LTDA | J5: 2900 | K5: 45687 | L5: 2900 | M5: =IF(OR(L5=0,L5=""),0,L5-J5) -> 0 | N5: Pix | O5: Recebido
A6: 8 | B6: 45627 | C6: 1 | D6: 9 | E6: 4 | F6: 262 | G6: 45659 | H6: 45663 | I6: =IF(E6="","",_xlfn.XLOOKUP(E6,'🏢 CLIENTES'!A:A,'🏢 CLIENTES'!B:B,"")) -> Consorcio Gb Osasco Tiete | J6: 3000 | K6: =TODAY() -> 46152 | L6: 0 | M6: =IF(OR(L6=0,L6=""),0,L6-J6) -> 0 | N6: Pix | O6: Vencido
A7: 3 | B7: 45627 | C7: 1 | D7: 16 | E7: 7 | F7: 258 | G7: 45659 | H7: 45667 | I7: =IF(E7="","",_xlfn.XLOOKUP(E7,'🏢 CLIENTES'!A:A,'🏢 CLIENTES'!B:B,"")) -> Fibertec Engenharia LTDA | J7: 15000 | K7: 45667 | L7: 15000 | M7: =IF(OR(L7=0,L7=""),0,L7-J7) -> 0 | N7: Boleto | O7: Recebido
A8: 5 | B8: 45627 | C8: 1 | D8: 6 | E8: 1 | F8: 259 | G8: 45659 | H8: 45687 | I8: =IF(E8="","",_xlfn.XLOOKUP(E8,'🏢 CLIENTES'!A:A,'🏢 CLIENTES'!B:B,"")) -> Celebre Obras e Servicos LTDA | J8: 20000 | K8: 45687 | L8: 20000 | M8: =IF(OR(L8=0,L8=""),0,L8-J8) -> 0 | N8: Pix | O8: Recebido
A9: 7 | B9: 45627 | C9: 1 | D9: 15 | E9: 1 | F9: 261 | G9: 45659 | H9: 45691 | I9: =IF(E9="","",_xlfn.XLOOKUP(E9,'🏢 CLIENTES'!A:A,'🏢 CLIENTES'!B:B,"")) -> Celebre Obras e Servicos LTDA | J9: 16000 | K9: 45705 | L9: 16000 | M9: =IF(OR(L9=0,L9=""),0,L9-J9) -> 0 | N9: Pix | O9: Recebido
A10: 9 | B10: 45658 | C10: 1 | D10: 10;13 | E10: 9 | F10: 264 | G10: 45691 | H10: 45693 | I10: =IF(E10="","",_xlfn.XLOOKUP(E10,'🏢 CLIENTES'!A:A,'🏢 CLIENTES'!B:B,"")) -> Polemica Servicos Basicos LTDA | J10: 30300 | K10: 45693 | L10: 30300 | M10: =IF(OR(L10=0,L10=""),0,L10-J10) -> 0 | N10: Boleto | O10: Recebido
A11: 10 | B11: 45658 | C11: 1 | D11: 20 | E11: 8 | F11: 266 | G11: 45691 | H11: 45693 | I11: =IF(E11="","",_xlfn.XLOOKUP(E11,'🏢 CLIENTES'!A:A,'🏢 CLIENTES'!B:B,"")) -> Consorcio Global Franca | J11: 12000 | K11: 45693 | L11: 12000 | M11: =IF(OR(L11=0,L11=""),0,L11-J11) -> 0 | N11: Boleto | O11: Recebido
A12: 12 | B12: 45658 | C12: 1 | D12: 14;17 | E12: 11 | F12: 265 | G12: 45691 | H12: 45693 | I12: =IF(E12="","",_xlfn.XLOOKUP(E12,'🏢 CLIENTES'!A:A,'🏢 CLIENTES'!B:B,"")) -> Zigurate Construcao LTDA | J12: 22000 | K12: 45705 | L12: 24384.8 | M12: =IF(OR(L12=0,L12=""),0,L12-J12) -> 2384.8 | N12: Boleto | O12: Recebido
A13: 11 | B13: 45658 | C13: 1 | D13: 16 | E13: 7 | F13: 263 | G13: 45691 | H13: 45698 | I13: =IF(E13="","",_xlfn.XLOOKUP(E13,'🏢 CLIENTES'!A:A,'🏢 CLIENTES'!B:B,"")) -> Fibertec Engenharia LTDA | J13: 15000 | K13: 45702 | L13: 15759.76 | M13: =IF(OR(L13=0,L13=""),0,L13-J13) -> 759.76 | N13: Pix | O13: Recebido
A14: 14 | B14: 45658 | C14: 1 | D14: 19 | E14: 7 | F14: 267 | G14: 45698 | H14: 45708 | I14: =IF(E14="","",_xlfn.XLOOKUP(E14,'🏢 CLIENTES'!A:A,'🏢 CLIENTES'!B:B,"")) -> Fibertec Engenharia LTDA | J14: 8800 | K14: 45708 | L14: 8800 | M14: =IF(OR(L14=0,L14=""),0,L14-J14) -> 0 | N14: Boleto | O14: Recebido
A15: 13 | B15: 45658 | C15: 1 | D15: 6 | E15: 1 | F15: 268 | G15: 45691 | H15: 45716 | I15: =IF(E15="","",_xlfn.XLOOKUP(E15,'🏢 CLIENTES'!A:A,'🏢 CLIENTES'!B:B,"")) -> Celebre Obras e Servicos LTDA | J15: 20000 | K15: 45716 | L15: 20000 | M15: =IF(OR(L15=0,L15=""),0,L15-J15) -> 0 | N15: Boleto | O15: Recebido
A16: 15 | B16: 45658 | C16: 1 | D16: 7 | E16: 2 | F16: 269 | G16: 45698 | H16: 45716 | I16: =IF(E16="","",_xlfn.XLOOKUP(E16,'🏢 CLIENTES'!A:A,'🏢 CLIENTES'!B:B,"")) -> Jwr Construcoes LTDA | J16: 2126.67 | K16: 45716 | L16: 2126.67 | M16: =IF(OR(L16=0,L16=""),0,L16-J16) -> 0 | N16: Boleto | O16: Recebido
A17: 16 | B17: 45658 | C17: 1 | D17: 21 | E17: 1 | F17: 270 | G17: 45705 | H17: 45719 | I17: =IF(E17="","",_xlfn.XLOOKUP(E17,'🏢 CLIENTES'!A:A,'🏢 CLIENTES'!B:B,"")) -> Celebre Obras e Servicos LTDA | J17: 15466.67 | K17: 45728 | L17: 15466.67 | M17: =IF(OR(L17=0,L17=""),0,L17-J17) -> 0 | N17: Pix | O17: Recebido
A18: 17 | B18: 45689 | C18: 1 | D18: 10;13 | E18: 9 | F18: 271 | G18: 45717 | H18: 45721 | I18: =IF(E18="","",_xlfn.XLOOKUP(E18,'🏢 CLIENTES'!A:A,'🏢 CLIENTES'!B:B,"")) -> Polemica Servicos Basicos LTDA | J18: 30300 | K18: 45721 | L18: 30300 | M18: =IF(OR(L18=0,L18=""),0,L18-J18) -> 0 | N18: Boleto | O18: Recebido
A19: 18 | B19: 45689 | C19: 1 | D19: 20 | E19: 8 | F19: 273 | G19: 45717 | H19: 45721 | I19: =IF(E19="","",_xlfn.XLOOKUP(E19,'🏢 CLIENTES'!A:A,'🏢 CLIENTES'!B:B,"")) -> Consorcio Global Franca | J19: 11100 | K19: 45721 | L19: 11100 | M19: =IF(OR(L19=0,L19=""),0,L19-J19) -> 0 | N19: Boleto | O19: Recebido
A20: 19 | B20: 45689 | C20: 1 | D20: 16 | E20: 7 | F20: 274 | G20: 45717 | H20: 45726 | I20: =IF(E20="","",_xlfn.XLOOKUP(E20,'🏢 CLIENTES'!A:A,'🏢 CLIENTES'!B:B,"")) -> Fibertec Engenharia LTDA | J20: 15000 | K20: 45726 | L20: 15000 | M20: =IF(OR(L20=0,L20=""),0,L20-J20) -> 0 | N20: Boleto | O20: Recebido
A21: 20 | B21: 45689 | C21: 1 | D21: 14;17 | E21: 11 | F21: 272 | G21: 45717 | H21: 45726 | I21: =IF(E21="","",_xlfn.XLOOKUP(E21,'🏢 CLIENTES'!A:A,'🏢 CLIENTES'!B:B,"")) -> Zigurate Construcao LTDA | J21: 22000 | K21: 45735 | L21: 23100 | M21: =IF(OR(L21=0,L21=""),0,L21-J21) -> 1100 | N21: Pix | O21: Recebido
A22: 22 | B22: 45689 | C22: 1 | D22: 19 | E22: 7 | F22: 275 | G22: 45721 | H22: 45736 | I22: =IF(E22="","",_xlfn.XLOOKUP(E22,'🏢 CLIENTES'!A:A,'🏢 CLIENTES'!B:B,"")) -> Fibertec Engenharia LTDA | J22: 12000 | K22: 45750 | L22: 12000 | M22: =IF(OR(L22=0,L22=""),0,L22-J22) -> 0 | N22: Boleto | O22: Recebido
A23: 21 | B23: 45689 | C23: 1 | D23: 6 | E23: 1 | F23: 276 | G23: 45721 | H23: 45747 | I23: =IF(E23="","",_xlfn.XLOOKUP(E23,'🏢 CLIENTES'!A:A,'🏢 CLIENTES'!B:B,"")) -> Celebre Obras e Servicos LTDA | J23: 20000 | K23: 45747 | L23: 20000 | M23: =IF(OR(L23=0,L23=""),0,L23-J23) -> 0 | N23: Pix | O23: Recebido
A24: 23 | B24: 45689 | C24: 1 | D24: 21 | E24: 1 | F24: 277 | G24: 45733 | H24: 45748 | I24: =IF(E24="","",_xlfn.XLOOKUP(E24,'🏢 CLIENTES'!A:A,'🏢 CLIENTES'!B:B,"")) -> Celebre Obras e Servicos LTDA | J24: 16000 | K24: 45754 | L24: 16000 | M24: =IF(OR(L24=0,L24=""),0,L24-J24) -> 0 | N24: Pix | O24: Recebido
A25: 24 | B25: 45717 | C25: 1 | D25: 10;13 | E25: 9 | F25: 278 | G25: 45748 | H25: 45752 | I25: =IF(E25="","",_xlfn.XLOOKUP(E25,'🏢 CLIENTES'!A:A,'🏢 CLIENTES'!B:B,"")) -> Polemica Servicos Basicos LTDA | J25: 30300 | K25: 45752 | L25: 30300 | M25: =IF(OR(L25=0,L25=""),0,L25-J25) -> 0 | N25: Boleto | O25: Recebido
A26: 25 | B26: 45717 | C26: 1 | D26: 20 | E26: 8 | F26: 280 | G26: 45748 | H26: 45755 | I26: =IF(E26="","",_xlfn.XLOOKUP(E26,'🏢 CLIENTES'!A:A,'🏢 CLIENTES'!B:B,"")) -> Consorcio Global Franca | J26: 12000 | K26: 45755 | L26: 12000 | M26: =IF(OR(L26=0,L26=""),0,L26-J26) -> 0 | N26: Boleto | O26: Recebido
A27: 26 | B27: 45717 | C27: 1 | D27: 16 | E27: 7 | F27: 282 | G27: 45748 | H27: 45757 | I27: =IF(E27="","",_xlfn.XLOOKUP(E27,'🏢 CLIENTES'!A:A,'🏢 CLIENTES'!B:B,"")) -> Fibertec Engenharia LTDA | J27: 15000 | K27: 45757 | L27: 15000 | M27: =IF(OR(L27=0,L27=""),0,L27-J27) -> 0 | N27: Boleto | O27: Recebido
A28: 27 | B28: 45717 | C28: 1 | D28: 14;17 | E28: 11 | F28: 279 | G28: 45748 | H28: 45757 | I28: =IF(E28="","",_xlfn.XLOOKUP(E28,'🏢 CLIENTES'!A:A,'🏢 CLIENTES'!B:B,"")) -> Zigurate Construcao LTDA | J28: 22000 | K28: 45763 | L28: 24273.32 | M28: =IF(OR(L28=0,L28=""),0,L28-J28) -> 2273.32 | N28: Boleto | O28: Recebido
A29: 28 | B29: 45717 | C29: 1 | D29: 19 | E29: 7 | F29: 283 | G29: 45748 | H29: 45767 | I29: =IF(E29="","",_xlfn.XLOOKUP(E29,'🏢 CLIENTES'!A:A,'🏢 CLIENTES'!B:B,"")) -> Fibertec Engenharia LTDA | J29: 3200 | K29: 45770 | L29: 3200 | M29: =IF(OR(L29=0,L29=""),0,L29-J29) -> 0 | N29: Boleto | O29: Recebido
A30: 29 | B30: 45717 | C30: 1 | D30: 6 | E30: 1 | F30: 281 | G30: 45748 | H30: 45777 | I30: =IF(E30="","",_xlfn.XLOOKUP(E30,'🏢 CLIENTES'!A:A,'🏢 CLIENTES'!B:B,"")) -> Celebre Obras e Servicos LTDA | J30: 20000 | K30: 45777 | L30: 20000 | M30: =IF(OR(L30=0,L30=""),0,L30-J30) -> 0 | N30: Pix | O30: Recebido
A31: 30 | B31: 45717 | C31: 1 | D31: 22 | E31: 1 | F31: 284 | G31: 45764 | H31: 45778 | I31: =IF(E31="","",_xlfn.XLOOKUP(E31,'🏢 CLIENTES'!A:A,'🏢 CLIENTES'!B:B,"")) -> Celebre Obras e Servicos LTDA | J31: 17000 | K31: 45783 | L31: 17000 | M31: =IF(OR(L31=0,L31=""),0,L31-J31) -> 0 | N31: Pix | O31: Recebido
A32: 31 | B32: 45748 | C32: 1 | D32: 10;13 | E32: 9 | F32: 285 | G32: 45778 | H32: 45782 | I32: =IF(E32="","",_xlfn.XLOOKUP(E32,'🏢 CLIENTES'!A:A,'🏢 CLIENTES'!B:B,"")) -> Polemica Servicos Basicos LTDA | J32: 30300 | K32: 45782 | L32: 30300 | M32: =IF(OR(L32=0,L32=""),0,L32-J32) -> 0 | N32: Boleto | O32: Recebido
A33: 32 | B33: 45748 | C33: 1 | D33: 20 | E33: 8 | F33: 287 | G33: 45778 | H33: 45785 | I33: =IF(E33="","",_xlfn.XLOOKUP(E33,'🏢 CLIENTES'!A:A,'🏢 CLIENTES'!B:B,"")) -> Consorcio Global Franca | J33: 12000 | K33: 45785 | L33: 12000 | M33: =IF(OR(L33=0,L33=""),0,L33-J33) -> 0 | N33: Boleto | O33: Recebido
A34: 34 | B34: 45748 | C34: 1 | D34: 14;17 | E34: 11 | F34: 286 | G34: 45778 | H34: 45786 | I34: =IF(E34="","",_xlfn.XLOOKUP(E34,'🏢 CLIENTES'!A:A,'🏢 CLIENTES'!B:B,"")) -> Zigurate Construcao LTDA | J34: 24000 | K34: 45796 | L34: 26560 | M34: =IF(OR(L34=0,L34=""),0,L34-J34) -> 2560 | N34: Boleto | O34: Recebido
A35: 33 | B35: 45748 | C35: 1 | D35: 16 | E35: 7 | F35: 289 | G35: 45778 | H35: 45787 | I35: =IF(E35="","",_xlfn.XLOOKUP(E35,'🏢 CLIENTES'!A:A,'🏢 CLIENTES'!B:B,"")) -> Fibertec Engenharia LTDA | J35: 15000 | K35: 45792 | L35: 16560 | M35: =IF(OR(L35=0,L35=""),0,L35-J35) -> 1560 | N35: Pix | O35: Recebido
A36: 35 | B36: 45748 | C36: 1 | D36: 23 | E36: 1 | F36: 288 | G36: 45778 | H36: 45807 | I36: =IF(E36="","",_xlfn.XLOOKUP(E36,'🏢 CLIENTES'!A:A,'🏢 CLIENTES'!B:B,"")) -> Celebre Obras e Servicos LTDA | J36: 21550 | K36: 45807 | L36: 21550 | M36: =IF(OR(L36=0,L36=""),0,L36-J36) -> 0 | N36: Pix | O36: Recebido
A37: 36 | B37: 45748 | C37: 1 | D37: 22 | E37: 1 | F37: 290 | G37: 45793 | H37: 45809 | I37: =IF(E37="","",_xlfn.XLOOKUP(E37,'🏢 CLIENTES'!A:A,'🏢 CLIENTES'!B:B,"")) -> Celebre Obras e Servicos LTDA | J37: 17000 | K37: 45814 | L37: 17000 | M37: =IF(OR(L37=0,L37=""),0,L37-J37) -> 0 | N37: Pix | O37: Recebido
A38: 37 | B38: 45778 | C38: 1 | D38: 13;24 | E38: 9 | F38: 291 | G38: 45809 | H38: 45813 | I38: =IF(E38="","",_xlfn.XLOOKUP(E38,'🏢 CLIENTES'!A:A,'🏢 CLIENTES'!B:B,"")) -> Polemica Servicos Basicos LTDA | J38: 32620 | K38: 45813 | L38: 32620 | M38: =IF(OR(L38=0,L38=""),0,L38-J38) -> 0 | N38: Boleto | O38: Recebido
A39: 38 | B39: 45778 | C39: 1 | D39: 20 | E39: 8 | F39: 293 | G39: 45809 | H39: 45816 | I39: =IF(E39="","",_xlfn.XLOOKUP(E39,'🏢 CLIENTES'!A:A,'🏢 CLIENTES'!B:B,"")) -> Consorcio Global Franca | J39: 9333.34 | K39: 45819 | L39: 9538.65 | M39: =IF(OR(L39=0,L39=""),0,L39-J39) -> 205.31 | N39: Boleto | O39: Recebido
A40: 39 | B40: 45778 | C40: 1 | D40: 14;17 | E40: 11 | F40: 292 | G40: 45809 | H40: 45817 | I40: =IF(E40="","",_xlfn.XLOOKUP(E40,'🏢 CLIENTES'!A:A,'🏢 CLIENTES'!B:B,"")) -> Zigurate Construcao LTDA | J40: 16000 | K40: 45825 | L40: 17685.28 | M40: =IF(OR(L40=0,L40=""),0,L40-J40) -> 1685.28 | N40: Pix | O40: Recebido
...

Sheet ↩️ REEMBOLSOS
A1: IDReembolso | B1: Tipo | C1: IDEmpresa | D1: IDContrato | E1: IDCliente | F1: IDVeiculo | G1: IDOrdServ | H1: IDMulta | I1: Recibo | J1: Emissão | K1: Vencimento | L1: Empresa | M1: ValorReembolso | N1: DataEntrada | O1: ValorRecebido | P1: Encargos de Faturamento | Q1: FormaRecebimento | R1: StatusRecebimento | S1: DocumentoRede
A2: 1 | B2: Transporte | C2: 1 | D2: 20 | E2: 8 | F2: 20 | I2: 12003 | J2: 45659 | K2: 45663 | L2: Consorcio Global Franca | M2: 2333.33 | N2: 45663 | O2: 2333.33 | P2: =IF(OR(O2=0,O2=""),0,O2-M2) -> 0 | Q2: Boleto | R2: Recebido
A3: 2 | B3: Multa de Trânsito | C3: 1 | D3: 9 | E3: 4 | F3: 6 | I3: 12004 | J3: 45674 | K3: 45687 | L3: Consorcio Gb Osasco Tiete | M3: 2010.28 | O3: 0 | P3: =IF(OR(O3=0,O3=""),0,O3-M3) -> 0 | Q3: Pix | R3: Vencido
A4: 3 | B4: Manutenção | C4: 1 | D4: 15 | E4: 1 | I4: 12005 | J4: 45659 | K4: 45691 | L4: Celebre Obras e Servicos LTDA | M4: 1669.389 | O4: 0 | P4: =IF(OR(O4=0,O4=""),0,O4-M4) -> 0 | Q4: Pix | R4: Cancelado
A5: 4 | B5: Franquia de Seguro | C5: 1 | D5: 13 | E5: 9 | F5: 46 | I5: 12006 | J5: 45691 | K5: 45693 | L5: Polemica Servicos Basicos LTDA | M5: 547 | N5: 45693 | O5: 547 | P5: =IF(OR(O5=0,O5=""),0,O5-M5) -> 0 | Q5: Boleto | R5: Recebido
A6: 5 | B6: Manutenção | C6: 1 | D6: 17 | E6: 11 | F6: 17 | I6: 12007 | J6: 45691 | K6: 45693 | L6: Zigurate Construcao LTDA | M6: 1100 | N6: 45693 | O6: 1100 | P6: =IF(OR(O6=0,O6=""),0,O6-M6) -> 0 | Q6: Boleto | R6: Recebido
A7: 6 | B7: Multa de Trânsito | C7: 1 | D7: 16 | E7: 7 | F7: 47 | I7: 12008 | J7: 45691 | K7: 45698 | L7: Fibertec Engenharia LTDA | M7: 195.23 | N7: 45698 | O7: 195.23 | P7: =IF(OR(O7=0,O7=""),0,O7-M7) -> 0 | Q7: Boleto | R7: Recebido
A8: 7 | B8: Indenização | C8: 1 | D8: 21 | E8: 1 | F8: 33 | I8: 12009 | J8: 45698 | K8: 45716 | L8: Celebre Obras e Servicos LTDA | M8: 6011.98 | N8: 45716 | O8: 6011.98 | P8: =IF(OR(O8=0,O8=""),0,O8-M8) -> 0 | Q8: Pix | R8: Recebido
A9: 8 | B9: Manutenção | C9: 1 | D9: 16 | E9: 7 | F9: 47 | I9: 12010 | J9: 45722 | K9: 45736 | L9: Fibertec Engenharia LTDA | M9: 6500 | N9: 45736 | O9: 6500 | P9: =IF(OR(O9=0,O9=""),0,O9-M9) -> 0 | Q9: Boleto | R9: Recebido
A10: 9 | B10: Manutenção | C10: 1 | D10: 10 | E10: 9 | F10: 42 | G10: OS-2025-0023 | I10: 12011 | J10: 45726 | K10: 45713 | L10: Polemica Servicos Basicos LTDA | M10: 2962.25 | N10: 45713 | O10: 2962.25 | P10: =IF(OR(O10=0,O10=""),0,O10-M10) -> 0 | Q10: Boleto | R10: Recebido
A11: 10 | B11: Multa de Trânsito | C11: 1 | D11: 14 | E11: 11 | F11: 24 | I11: 12012 | J11: 45764 | K11: 45782 | L11: Zigurate Construcao LTDA | M11: 2064.62 | N11: 45825 | O11: 2330.34 | P11: =IF(OR(O11=0,O11=""),0,O11-M11) -> 265.72 | Q11: Pix | R11: Recebido
A12: 11 | B12: Multa de Trânsito | C12: 1 | D12: 16 | E12: 7 | F12: 6 | I12: 12013 | J12: 45764 | K12: 45777 | L12: Fibertec Engenharia LTDA | M12: 3028 | N12: 45792 | O12: 3361.08 | P12: =IF(OR(O12=0,O12=""),0,O12-M12) -> 333.08 | Q12: Pix | R12: Recebido
A13: 12 | B13: Multa de Trânsito | C13: 1 | D13: 22 | E13: 1 | F13: 39 | I13: 12014 | J13: 45764 | K13: 45782 | L13: Celebre Obras e Servicos LTDA | M13: 390.48 | N13: 45849 | O13: 390.48 | P13: =IF(OR(O13=0,O13=""),0,O13-M13) -> 0 | Q13: Pix | R13: Recebido
A14: 13 | B14: Manutenção | C14: 1 | D14: 17 | E14: 11 | F14: 17 | G14: OS-2025-0045 | I14: 12015 | J14: 45778 | K14: 45786 | L14: Zigurate Construcao LTDA | M14: 932.13 | N14: 45796 | O14: 1031.54 | P14: =IF(OR(O14=0,O14=""),0,O14-M14) -> 99.41 | Q14: Boleto | R14: Recebido
A15: 14 | B15: Franquia de Seguro | C15: 1 | D15: 10 | E15: 9 | F15: 34 | I15: 12016 | J15: 45778 | K15: 45782 | L15: Polemica Servicos Basicos LTDA | M15: 659 | N15: 45782 | O15: 659 | P15: =IF(OR(O15=0,O15=""),0,O15-M15) -> 0 | Q15: Boleto | R15: Recebido
A16: 15 | B16: Manutenção | C16: 1 | D16: 22 | E16: 1 | I16: 12017 | J16: 45793 | K16: 45870 | L16: Celebre Obras e Servicos LTDA | M16: 3933.67 | O16: 0 | P16: =IF(OR(O16=0,O16=""),0,O16-M16) -> 0 | Q16: Pix | R16: Cancelado
A17: 16 | B17: Manutenção | C17: 1 | D17: 24 | E17: 9 | F17: 42 | G17: OS-2025-0004 | I17: 12018 | J17: 45809 | K17: 45813 | L17: Polemica Servicos Basicos LTDA | M17: 1318 | N17: 45813 | O17: 1318 | P17: =IF(OR(O17=0,O17=""),0,O17-M17) -> 0 | Q17: Boleto | R17: Recebido
A18: 17 | B18: Multa de Trânsito | C18: 1 | D18: 13 | E18: 9 | I18: 12019 | J18: 45809 | K18: 45835 | L18: Polemica Servicos Basicos LTDA | M18: 0 | O18: 0 | P18: =IF(OR(O18=0,O18=""),0,O18-M18) -> 0 | Q18: Boleto | R18: Cancelado
A19: 18 | B19: Manutenção | C19: 1 | D19: 24 | E19: 9 | F19: 43 | I19: 12020 | J19: 45839 | K19: 45843 | L19: Polemica Servicos Basicos LTDA | M19: 235 | N19: 45843 | O19: 235 | P19: =IF(OR(O19=0,O19=""),0,O19-M19) -> 0 | Q19: Boleto | R19: Recebido
A20: 19 | B20: Manutenção | C20: 1 | D20: 16 | E20: 7 | F20: 43 | G20: OS-2025-0068 | I20: 12021 | J20: 45839 | K20: 45848 | L20: Fibertec Engenharia LTDA | M20: 1450 | N20: 45854 | O20: 1450 | P20: =IF(OR(O20=0,O20=""),0,O20-M20) -> 0 | Q20: Pix | R20: Recebido
A21: 20 | B21: Manutenção | C21: 1 | D21: 22 | E21: 1 | F21: 41 | G21: OS-2025-0064 | I21: 12022 | J21: 45856 | K21: 45870 | L21: Celebre Obras e Servicos LTDA | M21: 366.2 | N21: 45874 | O21: 366.2 | P21: =IF(OR(O21=0,O21=""),0,O21-M21) -> 0 | Q21: Pix | R21: Recebido
B22: Manutenção | C22: 1 | D22: 22 | E22: 1 | F22: 41 | G22: OS-2025-0076 | I22: 12022 | J22: 45856 | K22: 45870 | L22: Celebre Obras e Servicos LTDA | M22: 2426.91 | N22: 45874 | O22: 2426.91 | P22: =IF(OR(O22=0,O22=""),0,O22-M22) -> 0 | Q22: Pix | R22: Recebido
B23: Manutenção | C23: 1 | D23: 22 | E23: 1 | F23: 39 | G23: OS-2025-0145 | I23: 12022 | J23: 45856 | K23: 45870 | L23: Celebre Obras e Servicos LTDA | M23: 3656.62 | N23: 45874 | O23: 3656.62 | P23: =IF(OR(O23=0,O23=""),0,O23-M23) -> 0 | Q23: Pix | R23: Recebido
A24: 21 | B24: Encargos de Faturamento | C24: 1 | D24: 22 | E24: 1 | I24: 12023 | J24: 45901 | K24: 45910 | L24: Celebre Obras e Servicos LTDA | M24: 0 | O24: 0 | P24: =IF(OR(O24=0,O24=""),0,O24-M24) -> 0 | Q24: Pix | R24: Cancelado
A25: 22 | B25: Manutenção | C25: 1 | D25: 9 | E25: 4 | I25: 12024 | J25: 45901 | K25: 45905 | L25: Consorcio Gb Osasco Tiete | M25: 22859 | O25: 0 | P25: =IF(OR(O25=0,O25=""),0,O25-M25) -> 0 | Q25: Pix | R25: Vencido
A26: 23 | B26: Multa de Trânsito | C26: 1 | D26: 22 | E26: 1 | F26: 44 | I26: 12025 | J26: 45901 | K26: 45915 | L26: Celebre Obras e Servicos LTDA | M26: 6526.18 | N26: 45922 | O26: 6526.18 | P26: =IF(OR(O26=0,O26=""),0,O26-M26) -> 0 | Q26: Pix | R26: Recebido
